{
 "cells": [
  {
   "cell_type": "code",
   "execution_count": 2,
   "id": "9615e31d",
   "metadata": {},
   "outputs": [
    {
     "name": "stderr",
     "output_type": "stream",
     "text": [
      "C:\\Users\\DELL\\anaconda3\\lib\\site-packages\\scipy\\__init__.py:146: UserWarning: A NumPy version >=1.16.5 and <1.23.0 is required for this version of SciPy (detected version 1.23.4\n",
      "  warnings.warn(f\"A NumPy version >={np_minversion} and <{np_maxversion}\"\n"
     ]
    }
   ],
   "source": [
    "import numpy as np\n",
    "import matplotlib.pyplot as plt\n",
    "import pandas as pd\n",
    "import tensorflow as tf\n",
    "from keras.models import Sequential"
   ]
  },
  {
   "cell_type": "code",
   "execution_count": 8,
   "id": "8e96b6e2",
   "metadata": {},
   "outputs": [
    {
     "name": "stdout",
     "output_type": "stream",
     "text": [
      "[array([[[0.]],\n",
      "\n",
      "       [[1.]],\n",
      "\n",
      "       [[0.]]], dtype=float32), array([0.], dtype=float32)]\n",
      "WARNING:tensorflow:Model was constructed with shape (None, 8, 1) for input KerasTensor(type_spec=TensorSpec(shape=(None, 8, 1), dtype=tf.float32, name='conv1d_5_input'), name='conv1d_5_input', description=\"created by layer 'conv1d_5_input'\"), but it was called on an input with incompatible shape (None,).\n"
     ]
    },
    {
     "ename": "ValueError",
     "evalue": "in user code:\n\n    File \"C:\\Users\\DELL\\anaconda3\\lib\\site-packages\\keras\\engine\\training.py\", line 2041, in predict_function  *\n        return step_function(self, iterator)\n    File \"C:\\Users\\DELL\\anaconda3\\lib\\site-packages\\keras\\engine\\training.py\", line 2027, in step_function  **\n        outputs = model.distribute_strategy.run(run_step, args=(data,))\n    File \"C:\\Users\\DELL\\anaconda3\\lib\\site-packages\\keras\\engine\\training.py\", line 2015, in run_step  **\n        outputs = model.predict_step(data)\n    File \"C:\\Users\\DELL\\anaconda3\\lib\\site-packages\\keras\\engine\\training.py\", line 1983, in predict_step\n        return self(x, training=False)\n    File \"C:\\Users\\DELL\\anaconda3\\lib\\site-packages\\keras\\utils\\traceback_utils.py\", line 70, in error_handler\n        raise e.with_traceback(filtered_tb) from None\n    File \"C:\\Users\\DELL\\anaconda3\\lib\\site-packages\\keras\\engine\\input_spec.py\", line 250, in assert_input_compatibility\n        raise ValueError(\n\n    ValueError: Exception encountered when calling layer \"sequential_5\" \"                 f\"(type Sequential).\n    \n    Input 0 of layer \"conv1d_5\" is incompatible with the layer: expected min_ndim=3, found ndim=1. Full shape received: (None,)\n    \n    Call arguments received by layer \"sequential_5\" \"                 f\"(type Sequential):\n      • inputs=tf.Tensor(shape=(None,), dtype=int32)\n      • training=False\n      • mask=None\n",
     "output_type": "error",
     "traceback": [
      "\u001b[1;31m---------------------------------------------------------------------------\u001b[0m",
      "\u001b[1;31mValueError\u001b[0m                                Traceback (most recent call last)",
      "\u001b[1;32m~\\AppData\\Local\\Temp/ipykernel_7956/3426867228.py\u001b[0m in \u001b[0;36m<module>\u001b[1;34m\u001b[0m\n\u001b[0;32m     13\u001b[0m \u001b[0mprint\u001b[0m\u001b[1;33m(\u001b[0m\u001b[0mmodel\u001b[0m\u001b[1;33m.\u001b[0m\u001b[0mget_weights\u001b[0m\u001b[1;33m(\u001b[0m\u001b[1;33m)\u001b[0m\u001b[1;33m)\u001b[0m\u001b[1;33m\u001b[0m\u001b[1;33m\u001b[0m\u001b[0m\n\u001b[0;32m     14\u001b[0m \u001b[1;31m#applying filter to input data\u001b[0m\u001b[1;33m\u001b[0m\u001b[1;33m\u001b[0m\u001b[0m\n\u001b[1;32m---> 15\u001b[1;33m \u001b[0myhat\u001b[0m\u001b[1;33m=\u001b[0m\u001b[0mmodel\u001b[0m\u001b[1;33m.\u001b[0m\u001b[0mpredict\u001b[0m\u001b[1;33m(\u001b[0m\u001b[0mdata\u001b[0m\u001b[1;33m)\u001b[0m\u001b[1;33m\u001b[0m\u001b[1;33m\u001b[0m\u001b[0m\n\u001b[0m\u001b[0;32m     16\u001b[0m \u001b[0mprint\u001b[0m\u001b[1;33m(\u001b[0m\u001b[0myhat\u001b[0m\u001b[1;33m)\u001b[0m\u001b[1;33m\u001b[0m\u001b[1;33m\u001b[0m\u001b[0m\n",
      "\u001b[1;32m~\\anaconda3\\lib\\site-packages\\keras\\utils\\traceback_utils.py\u001b[0m in \u001b[0;36merror_handler\u001b[1;34m(*args, **kwargs)\u001b[0m\n\u001b[0;32m     68\u001b[0m             \u001b[1;31m# To get the full stack trace, call:\u001b[0m\u001b[1;33m\u001b[0m\u001b[1;33m\u001b[0m\u001b[0m\n\u001b[0;32m     69\u001b[0m             \u001b[1;31m# `tf.debugging.disable_traceback_filtering()`\u001b[0m\u001b[1;33m\u001b[0m\u001b[1;33m\u001b[0m\u001b[0m\n\u001b[1;32m---> 70\u001b[1;33m             \u001b[1;32mraise\u001b[0m \u001b[0me\u001b[0m\u001b[1;33m.\u001b[0m\u001b[0mwith_traceback\u001b[0m\u001b[1;33m(\u001b[0m\u001b[0mfiltered_tb\u001b[0m\u001b[1;33m)\u001b[0m \u001b[1;32mfrom\u001b[0m \u001b[1;32mNone\u001b[0m\u001b[1;33m\u001b[0m\u001b[1;33m\u001b[0m\u001b[0m\n\u001b[0m\u001b[0;32m     71\u001b[0m         \u001b[1;32mfinally\u001b[0m\u001b[1;33m:\u001b[0m\u001b[1;33m\u001b[0m\u001b[1;33m\u001b[0m\u001b[0m\n\u001b[0;32m     72\u001b[0m             \u001b[1;32mdel\u001b[0m \u001b[0mfiltered_tb\u001b[0m\u001b[1;33m\u001b[0m\u001b[1;33m\u001b[0m\u001b[0m\n",
      "\u001b[1;32m~\\anaconda3\\lib\\site-packages\\keras\\engine\\training.py\u001b[0m in \u001b[0;36mtf__predict_function\u001b[1;34m(iterator)\u001b[0m\n\u001b[0;32m     13\u001b[0m                 \u001b[1;32mtry\u001b[0m\u001b[1;33m:\u001b[0m\u001b[1;33m\u001b[0m\u001b[1;33m\u001b[0m\u001b[0m\n\u001b[0;32m     14\u001b[0m                     \u001b[0mdo_return\u001b[0m \u001b[1;33m=\u001b[0m \u001b[1;32mTrue\u001b[0m\u001b[1;33m\u001b[0m\u001b[1;33m\u001b[0m\u001b[0m\n\u001b[1;32m---> 15\u001b[1;33m                     \u001b[0mretval_\u001b[0m \u001b[1;33m=\u001b[0m \u001b[0mag__\u001b[0m\u001b[1;33m.\u001b[0m\u001b[0mconverted_call\u001b[0m\u001b[1;33m(\u001b[0m\u001b[0mag__\u001b[0m\u001b[1;33m.\u001b[0m\u001b[0mld\u001b[0m\u001b[1;33m(\u001b[0m\u001b[0mstep_function\u001b[0m\u001b[1;33m)\u001b[0m\u001b[1;33m,\u001b[0m \u001b[1;33m(\u001b[0m\u001b[0mag__\u001b[0m\u001b[1;33m.\u001b[0m\u001b[0mld\u001b[0m\u001b[1;33m(\u001b[0m\u001b[0mself\u001b[0m\u001b[1;33m)\u001b[0m\u001b[1;33m,\u001b[0m \u001b[0mag__\u001b[0m\u001b[1;33m.\u001b[0m\u001b[0mld\u001b[0m\u001b[1;33m(\u001b[0m\u001b[0miterator\u001b[0m\u001b[1;33m)\u001b[0m\u001b[1;33m)\u001b[0m\u001b[1;33m,\u001b[0m \u001b[1;32mNone\u001b[0m\u001b[1;33m,\u001b[0m \u001b[0mfscope\u001b[0m\u001b[1;33m)\u001b[0m\u001b[1;33m\u001b[0m\u001b[1;33m\u001b[0m\u001b[0m\n\u001b[0m\u001b[0;32m     16\u001b[0m                 \u001b[1;32mexcept\u001b[0m\u001b[1;33m:\u001b[0m\u001b[1;33m\u001b[0m\u001b[1;33m\u001b[0m\u001b[0m\n\u001b[0;32m     17\u001b[0m                     \u001b[0mdo_return\u001b[0m \u001b[1;33m=\u001b[0m \u001b[1;32mFalse\u001b[0m\u001b[1;33m\u001b[0m\u001b[1;33m\u001b[0m\u001b[0m\n",
      "\u001b[1;31mValueError\u001b[0m: in user code:\n\n    File \"C:\\Users\\DELL\\anaconda3\\lib\\site-packages\\keras\\engine\\training.py\", line 2041, in predict_function  *\n        return step_function(self, iterator)\n    File \"C:\\Users\\DELL\\anaconda3\\lib\\site-packages\\keras\\engine\\training.py\", line 2027, in step_function  **\n        outputs = model.distribute_strategy.run(run_step, args=(data,))\n    File \"C:\\Users\\DELL\\anaconda3\\lib\\site-packages\\keras\\engine\\training.py\", line 2015, in run_step  **\n        outputs = model.predict_step(data)\n    File \"C:\\Users\\DELL\\anaconda3\\lib\\site-packages\\keras\\engine\\training.py\", line 1983, in predict_step\n        return self(x, training=False)\n    File \"C:\\Users\\DELL\\anaconda3\\lib\\site-packages\\keras\\utils\\traceback_utils.py\", line 70, in error_handler\n        raise e.with_traceback(filtered_tb) from None\n    File \"C:\\Users\\DELL\\anaconda3\\lib\\site-packages\\keras\\engine\\input_spec.py\", line 250, in assert_input_compatibility\n        raise ValueError(\n\n    ValueError: Exception encountered when calling layer \"sequential_5\" \"                 f\"(type Sequential).\n    \n    Input 0 of layer \"conv1d_5\" is incompatible with the layer: expected min_ndim=3, found ndim=1. Full shape received: (None,)\n    \n    Call arguments received by layer \"sequential_5\" \"                 f\"(type Sequential):\n      • inputs=tf.Tensor(shape=(None,), dtype=int32)\n      • training=False\n      • mask=None\n"
     ]
    }
   ],
   "source": [
    "from keras.layers import Conv1D\n",
    "from numpy import asarray\n",
    "data=np.asarray([0,0,0,1,1,0,0,0])\n",
    "data.reshape(1,8,1)\n",
    "#create model\n",
    "model=Sequential()\n",
    "model.add(Conv1D(1,3,input_shape=(8,1)))\n",
    "#define a vertical line detector\n",
    "weights=[asarray([[[0]],[[1]],[[0]]]),asarray([0.0])]\n",
    "#store the weights in the model\n",
    "model.set_weights(weights)\n",
    "#confirm they were stored\n",
    "print(model.get_weights())\n",
    "#applying filter to input data\n",
    "yhat=model.predict(data)\n",
    "print(yhat)"
   ]
  },
  {
   "cell_type": "code",
   "execution_count": null,
   "id": "5d36376c",
   "metadata": {},
   "outputs": [],
   "source": []
  }
 ],
 "metadata": {
  "kernelspec": {
   "display_name": "Python 3 (ipykernel)",
   "language": "python",
   "name": "python3"
  },
  "language_info": {
   "codemirror_mode": {
    "name": "ipython",
    "version": 3
   },
   "file_extension": ".py",
   "mimetype": "text/x-python",
   "name": "python",
   "nbconvert_exporter": "python",
   "pygments_lexer": "ipython3",
   "version": "3.9.7"
  }
 },
 "nbformat": 4,
 "nbformat_minor": 5
}
